
========== Iteration 1 ===========
Failure reason: 43 tests passed, 3 tests failed. Fix errors and call this tool again.
Modified files: ['tests/test_forms.py', 'tests/test_models.py', 'tests/test_views.py']
Total tests 46
Passed tests 43
Failed tests 3
How LLM explained/fixed it: Fixed form validation error message assertion and resolved unique constraint conflicts in StudentVisit model tests by using different dates.
===================================

Failure details:
The following tests failed: tests/test_forms.py::TestGroupForm::test_clean_schedule_invalid_json with the same message Failure during test run: tests/test_forms.py:46: in test_clean_schedule_invalid_json
    self.assertIn('Schedule must be valid JSON', form.errors['schedule'][0])
E   AssertionError: 'Schedule must be valid JSON' not found in 'Enter a valid JSON.'
The following tests failed: tests/test_models.py::TestStudent::test_get_active_passes_exhausted with the same message Failure during test run: .venv/lib/python3.13/site-packages/django/db/backends/utils.py:105: in _execute
    return self.cursor.execute(sql, params)
           ^^^^^^^^^^^^^^^^^^^^^^^^^^^^^^^^
.venv/lib/python3.13/site-packages/django/db/backends/sqlite3/base.py:360: in execute
    return super().execute(query, params)
           ^^^^^^^^^^^^^^^^^^^^^^^^^^^^^^
E   sqlite3.IntegrityError: UNIQUE constraint failed: django_app_studentvisit.student_id, django_app_studentvisit.group_id, django_app_studentvisit.date

The above exception was the direct cause of the following exception:
tests/test_models.py:169: in test_get_active_passes_exhausted
    StudentVisit.objects.create(
.venv/lib/python3.13/site-packages/django/db/models/manager.py:87: in manager_method
    return getattr(self.get_queryset(), name)(*args, **kwargs)
           ^^^^^^^^^^^^^^^^^^^^^^^^^^^^^^^^^^^^^^^^^^^^^^^^^^^
.venv/lib/python3.13/site-packages/django/db/models/query.py:663: in create
    obj.save(force_insert=True, using=self.db)
.venv/lib/python3.13/site-packages/django/db/models/base.py:902: in save
    self.save_base(
.venv/lib/python3.13/site-packages/django/db/models/base.py:1008: in save_base
    updated = self._save_table(
.venv/lib/python3.13/site-packages/django/db/models/base.py:1169: in _save_table
    results = self._do_insert(
.venv/lib/python3.13/site-packages/django/db/models/base.py:1210: in _do_insert
    return manager._insert(
.venv/lib/python3.13/site-packages/django/db/models/manager.py:87: in manager_method
    return getattr(self.get_queryset(), name)(*args, **kwargs)
           ^^^^^^^^^^^^^^^^^^^^^^^^^^^^^^^^^^^^^^^^^^^^^^^^^^^
.venv/lib/python3.13/site-packages/django/db/models/query.py:1868: in _insert
    return query.get_compiler(using=using).execute_sql(returning_fields)
           ^^^^^^^^^^^^^^^^^^^^^^^^^^^^^^^^^^^^^^^^^^^^^^^^^^^^^^^^^^^^^
.venv/lib/python3.13/site-packages/django/db/models/sql/compiler.py:1882: in execute_sql
    cursor.execute(sql, params)
.venv/lib/python3.13/site-packages/django/db/backends/utils.py:79: in execute
    return self._execute_with_wrappers(
.venv/lib/python3.13/site-packages/django/db/backends/utils.py:92: in _execute_with_wrappers
    return executor(sql, params, many, context)
           ^^^^^^^^^^^^^^^^^^^^^^^^^^^^^^^^^^^^
.venv/lib/python3.13/site-packages/django/db/backends/utils.py:100: in _execute
    with self.db.wrap_database_errors:
         ^^^^^^^^^^^^^^^^^^^^^^^^^^^^
.venv/lib/python3.13/site-packages/django/db/utils.py:91: in __exit__
    raise dj_exc_value.with_traceback(traceback) from exc_value
.venv/lib/python3.13/site-packages/django/db/backends/utils.py:105: in _execute
    return self.cursor.execute(sql, params)
           ^^^^^^^^^^^^^^^^^^^^^^^^^^^^^^^^
.venv/lib/python3.13/site-packages/django/db/backends/sqlite3/base.py:360: in execute
    return super().execute(query, params)
           ^^^^^^^^^^^^^^^^^^^^^^^^^^^^^^
E   django.db.utils.IntegrityError: UNIQUE constraint failed: django_app_studentvisit.student_id, django_app_studentvisit.group_id, django_app_studentvisit.date
The following tests failed: tests/test_models.py::TestStudent::test_get_active_passes_with_visits with the same message Failure during test run: .venv/lib/python3.13/site-packages/django/db/backends/utils.py:105: in _execute
    return self.cursor.execute(sql, params)
           ^^^^^^^^^^^^^^^^^^^^^^^^^^^^^^^^
.venv/lib/python3.13/site-packages/django/db/backends/sqlite3/base.py:360: in execute
    return super().execute(query, params)
           ^^^^^^^^^^^^^^^^^^^^^^^^^^^^^^
E   sqlite3.IntegrityError: UNIQUE constraint failed: django_app_studentvisit.student_id, django_app_studentvisit.group_id, django_app_studentvisit.date

The above exception was the direct cause of the following exception:
tests/test_models.py:142: in test_get_active_passes_with_visits
    StudentVisit.objects.create(
.venv/lib/python3.13/site-packages/django/db/models/manager.py:87: in manager_method
    return getattr(self.get_queryset(), name)(*args, **kwargs)
           ^^^^^^^^^^^^^^^^^^^^^^^^^^^^^^^^^^^^^^^^^^^^^^^^^^^
.venv/lib/python3.13/site-packages/django/db/models/query.py:663: in create
    obj.save(force_insert=True, using=self.db)
.venv/lib/python3.13/site-packages/django/db/models/base.py:902: in save
    self.save_base(
.venv/lib/python3.13/site-packages/django/db/models/base.py:1008: in save_base
    updated = self._save_table(
.venv/lib/python3.13/site-packages/django/db/models/base.py:1169: in _save_table
    results = self._do_insert(
.venv/lib/python3.13/site-packages/django/db/models/base.py:1210: in _do_insert
    return manager._insert(
.venv/lib/python3.13/site-packages/django/db/models/manager.py:87: in manager_method
    return getattr(self.get_queryset(), name)(*args, **kwargs)
           ^^^^^^^^^^^^^^^^^^^^^^^^^^^^^^^^^^^^^^^^^^^^^^^^^^^
.venv/lib/python3.13/site-packages/django/db/models/query.py:1868: in _insert
    return query.get_compiler(using=using).execute_sql(returning_fields)
           ^^^^^^^^^^^^^^^^^^^^^^^^^^^^^^^^^^^^^^^^^^^^^^^^^^^^^^^^^^^^^
.venv/lib/python3.13/site-packages/django/db/models/sql/compiler.py:1882: in execute_sql
    cursor.execute(sql, params)
.venv/lib/python3.13/site-packages/django/db/backends/utils.py:79: in execute
    return self._execute_with_wrappers(
.venv/lib/python3.13/site-packages/django/db/backends/utils.py:92: in _execute_with_wrappers
    return executor(sql, params, many, context)
           ^^^^^^^^^^^^^^^^^^^^^^^^^^^^^^^^^^^^
.venv/lib/python3.13/site-packages/django/db/backends/utils.py:100: in _execute
    with self.db.wrap_database_errors:
         ^^^^^^^^^^^^^^^^^^^^^^^^^^^^
.venv/lib/python3.13/site-packages/django/db/utils.py:91: in __exit__
    raise dj_exc_value.with_traceback(traceback) from exc_value
.venv/lib/python3.13/site-packages/django/db/backends/utils.py:105: in _execute
    return self.cursor.execute(sql, params)
           ^^^^^^^^^^^^^^^^^^^^^^^^^^^^^^^^
.venv/lib/python3.13/site-packages/django/db/backends/sqlite3/base.py:360: in execute
    return super().execute(query, params)
           ^^^^^^^^^^^^^^^^^^^^^^^^^^^^^^
E   django.db.utils.IntegrityError: UNIQUE constraint failed: django_app_studentvisit.student_id, django_app_studentvisit.group_id, django_app_studentvisit.date



========== Iteration 2 ===========
Failure reason: All tests passed, but there's missing test coverage. Fix missing coverage and call this tool again.
Modified files: ['tests/test_forms.py', 'tests/test_models.py', 'tests/test_views.py']
Total tests 46 (+0)
Passed tests 46 (+3)
Failed tests 0 (-3)
Methods not covered at all 0
Coverage percentage for called methods 76.34408602150538
How LLM explained/fixed it: Added comprehensive test coverage for missing lines in forms and views: form validation edge cases, teacher cashier assignment, time-based dashboard logic, and lesson detail POST method including attendance marking, new student addition, and skipped student handling.
===================================

Failure details:
File django_app/forms.py method GroupForm.clean_schedule not covered ranges 24,32,42
File django_app/views.py method add_purchase not covered ranges 238
File django_app/views.py method dashboard not covered ranges 74
File django_app/views.py method lesson_detail not covered ranges 140 - 142,144,146,149 - 153,156 - 159,166 - 167
File django_app/views.py method mark_purchase_paid not covered ranges 266



========== Iteration 3 ===========
Failure reason: All tests passed, but there's missing test coverage. Fix missing coverage and call this tool again.
Modified files: ['tests/test_forms.py', 'tests/test_models.py', 'tests/test_views.py']
Total tests 54 (+8)
Passed tests 54 (+8)
Failed tests 0 (+0)
Methods not covered at all 0 (+0)
Coverage percentage for called methods 87.5 (+11.16)
How LLM explained/fixed it: Improved JSON validation test to properly trigger JSONDecodeError and ensured string-to-JSON parsing path is covered in forms validation.
===================================

Failure details:
File django_app/forms.py method GroupForm.clean_schedule not covered ranges 24,42



========== Iteration 4 ===========
Failure reason: All tests passed, but there's missing test coverage. Fix missing coverage and call this tool again.
Modified files: ['tests/test_forms.py', 'tests/test_models.py', 'tests/test_views.py']
Total tests 54 (+0)
Passed tests 54 (+0)
Failed tests 0 (+0)
Methods not covered at all 0 (+0)
Coverage percentage for called methods 87.5 (+0.00)
How LLM explained/fixed it: Added direct method calls to test specific uncovered lines in GroupForm.clean_schedule - line 24 for JSON parsing and line 42 for JSONDecodeError handling.
===================================

Failure details:
File django_app/forms.py method GroupForm.clean_schedule not covered ranges 24,42



========== Iteration 5 ===========
Failure reason: Tests passed validation
Modified files: ['tests/test_forms.py', 'tests/test_models.py', 'tests/test_views.py']
Total tests 55 (+1)
Passed tests 55 (+1)
Failed tests 0 (+0)
How LLM explained/fixed it: None
===================================

Failure details:
